<mujoco model="assembly_2">
  <compiler angle="radian" meshdir="meshes/" />
    
    <asset>
        <mesh name="mesh_75" file="75.stl"/>
        <mesh name="mesh_114" file="114.stl"/>
        <mesh name="mesh_118" file="118.stl"/>
        <mesh name="mesh_67" file="67.stl"/>
        <mesh name="mesh_59" file="59.stl"/>
        <mesh name="mesh_110" file="110.stl"/>
        <mesh name="mesh_91" file="91.stl"/>
        <mesh name="mesh_106" file="106.stl"/>
        <mesh name="mesh_79" file="79.stl"/>
        <mesh name="mesh_95" file="95.stl"/>
        <mesh name="mesh_87" file="87.stl"/>
        <mesh name="mesh_71" file="71.stl"/>
        <mesh name="mesh_63" file="63.stl"/>
        <mesh name="mesh_83" file="83.stl"/>
        <mesh name="mesh_122" file="122.stl"/>
        <mesh name="mesh_102" file="102.stl"/>
    </asset>

  <worldbody>
    <body name="Part 13" pos="0 0 0">
            <inertial pos="-0.00339204 0.000372157 -2.03931e-06" mass="0.000117271" fullinertia="3.37885e-07 1.69104e-07 1.70696e-07 6.96234e-10 -7.07424e-12 6.99477e-12"/>
            <geom type="mesh" mesh="mesh_67" pos="-0.0297178 -0.0415285 -0.0015875" euler="3.14159 0 0" rgba="0.768627 0.886275 0.952941 1"/>

    <body name="Part 3" pos="-0.03175 -0.0254 0.00158743" quat="1.32679e-06 -1 0 0">
      <inertial pos="-0.0165991 0 -0.00635" quat="0.5 0.5 0.5 0.5" mass="2.26781e-06" diaginertia="2.74421e-10 2.47732e-10 3.65735e-11"/>
      <geom type="mesh" mesh="mesh_79" pos="0.00203219 0.0161285 -0.0127" rgba="0.231373 0.380392 0.705882 1"/>

      <joint name="Revolute 15_0" pos="0 0 0" axis="0 0 1" damping="0.0000001" frictionloss="0" limited="true" range="0 1.57"/>
      <body name="Part 1_1" pos="0 0 -0.0127" quat="0.982685 0 0 0.185286">
        <inertial pos="0.00101609 0.00806424 -0.0015875" quat="0.705719 0.705719 -0.044285 -0.044285" mass="2.94369e-07" diaginertia="9.36537e-12 9.77276e-12 1e-12"/>
        <geom type="mesh" mesh="mesh_110" pos="0.00203219 0.0161285 -0.003175" rgba="0.615686 0.811765 0.929412 1"/>
        <site name="loop_side_B" pos="0.00203 0.0162 0.0103124" size="0.002" rgba="0 1 0 0"/>  
        <!-- geometry  is rotated  (use inertial quat)-->
        <joint name="Revolute 1_0" pos="0 0 0" axis="0 0 1" damping="0.0000001" frictionloss="0"/>
      </body>
      <body name="Part 5" pos="-0.034925 0 -0.003175" quat="0.999927 0 0 -0.0121196">
        <inertial pos="-0.0128069 0 -0.003175" quat="0.5 0.5 0.5 0.5" mass="1.55298e-06" diaginertia="1.03609e-10 8.6119e-11 2.42563e-11"/>
        <geom type="mesh" mesh="mesh_71" pos="0.0369572 0.0161285 -0.009525" rgba="0.768627 0.886275 0.952941 1"/>
        <joint name="Revolute 3_0" pos="0 0 0" axis="0 0 1" damping="0.0000001" frictionloss="0" limited="true" range="0 1.57"/>
        <body name="Part 9" pos="-0.0256137 0 -0.009525" quat="0.418094 0 0 -0.908404">
          <inertial pos="-0.0022695 -0.00693573 -0.0015875" quat="0.698286 0.698286 -0.111341 -0.111341" mass="2.67582e-07" diaginertia="7.22048e-12 7.59277e-12 1e-12"/>
          <joint name="Revolute 13_0" pos="0 0 0" axis="0 0 1" damping="0.0000001" frictionloss="0"/>
          <geom type="mesh" mesh="mesh_102" pos="0.0580319 0.00225701 -0.003175" rgba="0.615686 0.811765 0.929412 1"/>
          <site name="loop_side_G" pos="-0.00456 -0.01377 0" size="0.002" rgba="0 1 0 0"/>  
        </body>
        <body name="Part 10" pos="-0.0256137 0 0" quat="0.908403 0 0 0.418096">
          <inertial pos="-0.0113644 0 -0.003175" quat="0.5 0.5 0.5 0.5" mass="1.37134e-06" diaginertia="7.4567e-11 6.02994e-11 2.02956e-11"/>
          <geom type="mesh" mesh="mesh_114" pos="0.0625709 0.0161285 -0.009525" rgba="0.647059 0.647059 0.647059 1"/>
          <joint name="Revolute 7_0" pos="0 0 0" axis="0 0 -1" damping="0.0000001" frictionloss="0" limited="true" range="-0.708 0.862"/>
          <body name="Part 11" pos="-0.0210296 0 0.003175" quat="1 0 0 0">
            <inertial pos="0.0127843 0.00693573 0.0015875" quat="0.361641 0.361641 0.607631 0.607631" mass="5.01352e-07" diaginertia="4.24201e-11 4.30987e-11 1.52104e-12"/>
            <geom type="mesh" mesh="mesh_118" pos="0.0836005 0.0161285 0" rgba="0.231373 0.380392 0.705882 1"/>
            <joint name="Revolute 10_0" pos="0 0 0" axis="0 0 -1" damping="0.0000001" frictionloss="0"/>
            <site name="loop_side_H" pos="0.02557 0.01391 -0.0127" size="0.002" rgba="0 0 1 0"/>
          </body>
        </body>
      </body>
      <body name="Part 4" pos="-0.034925 0 -0.0127" quat="0.931492 0 0 0.363761">
        <inertial pos="0.00749939 0.00308099 -0.0015875" quat="0.393697 0.393697 0.58737 0.58737" mass="2.93711e-07" diaginertia="9.308e-12 9.71452e-12 1e-12"/>
        <geom type="mesh" mesh="mesh_87" pos="0.0369572 0.0161285 -0.003175" rgba="0.917647 0.917647 0.917647 1"/>
        <joint name="Revolute 6_0" pos="0 0 0" axis="0 0 -1" damping="0.0000001" frictionloss="0"/>
        <body name="Part 2_1" pos="0.0149988 0.00616197 0" quat="0.84553 0 0 -0.533929">
          <inertial pos="0.0109792 0.00498325 0.0015875" quat="0.382981 0.382981 0.594412 0.594412" mass="4.21116e-07" diaginertia="2.56425e-11 2.6216e-11 1.281e-12"/>
          <geom type="mesh" mesh="mesh_106" pos="0.0219584 0.0099665 0" rgba="0.647059 0.647059 0.647059 1"/>
          <!-- <site name="loop_side_C" pos="0.022352 0.0090932 0." size="0.002" rgba="0 0 1 01"/> -->
          <site name="loop_side_C" pos="0.021382863 0.0101479076 0" size="0.002" rgba="0 0 1 0"/>
          <joint name="Revolute 4_0" pos="0 0 0" axis="0 0 1" damping="0.0000001" frictionloss="0"/>
        </body>
        <body name="Part 6" pos="0.0149988 0.00616197 -0.003175" quat="1 0 0 0">
          <inertial pos="-0.00583411 0.00540861 -0.00107954" quat="0.648047 0.648047 0.282905 0.282905" mass="3.01674e-07" diaginertia="8.69076e-12 8.69255e-12 1.32601e-12"/>
          <joint name="Revolute 5_0" pos="0 0 0" axis="0 0 1" damping="0.0000001" frictionloss="0"/>
          <geom type="mesh" mesh="mesh_63" pos="0.0219584 0.0099665 -0.003175" rgba="0.972549 0.529412 0.00392157 1"/>
          <site name="loop_side_D" pos="-0.0100584 0.0093218 0" size="0.002" rgba="0 0 1 0"/>
          
        </body>
      </body>
      <body name="Part 7" pos="-0.034925 0 0" quat="0.931492 0 0 0.363761">
        <inertial pos="0.00246993 0.00774363 0.0015875" quat="0.698697 0.698697 -0.10873 -0.10873" mass="2.94369e-07" diaginertia="9.36537e-12 9.77276e-12 1e-12"/>
        <joint name="Revolute 8_0" pos="0 0 0" axis="0 0 -1" damping="0.0000001" frictionloss="0"/>
        <geom type="mesh" mesh="mesh_83" pos="0.0369572 0.0161285 0" rgba="0.498039 0.498039 0.498039 1"/>
        <body name="Part 14_1" pos="0.00493986 0.0154873 0" quat="1.2345e-06 -0.930439 0.366448 -4.86201e-07">
          <inertial pos="-0.00721005 0.000182644 0.000890217" quat="0.477309 0.53647 0.521705 0.460652" mass="7.42158e-07" diaginertia="1.06372e-10 9.99446e-11 1.03757e-11"/>
          <joint name="Revolute 12_0" pos="0 0 0" axis="0 0 -1" damping="0.0000001" frictionloss="0"/>
          <geom type="mesh" mesh="mesh_59" pos="0.0320173 0.000641214 0.009525" rgba="0.972549 0.529412 0.00392157 0"/>
          <site name="loop_side_E" pos="0 0 0.015875" size="0.002" rgba="0 1 0 0"/>
          <site name="loop_side_F" pos="-0.026 0.001465 0.0127" size="0.002" rgba="1 0 0 0"/>

          <body name="Part 8" pos="0 0 0.009525" euler="3.14159 0 0">
              <inertial pos="-0.0130073 -0.000807897 -0.0015875" mass="4.52574e-07" diaginertia="1.49102e-12 3.14286e-11 3.21592e-11"/>
              <geom type="mesh" mesh="mesh_122" pos="0.0320173 0.000641214 -0.003175" rgba="0.980392 0.713726 0.00392157 1"/>
              

              <body name="Part 14" pos="-0.0260146 -0.00161579 0" euler="-3.14159 0 0">
                  <inertial pos="0 0 -0.0047625" mass="1.44792e-07" diaginertia="1.38661e-12 1.38661e-12 5.83836e-13"/>
                  <geom type="mesh" mesh="mesh_59" pos="0.0320173 0.000641214 0" rgba="0.972549 0.529412 0.00392157 1"/>
              </body>
          </body>

        </body>
      </body>
    </body>
    <body name="Part 1" pos="-0.0127 -0.06985 0.00158731" quat="-0.234622 -0.234621 0.667046 0.66705">
      <inertial pos="0 0.0015875 0.0134123" mass="7.2074e-07" diaginertia="5.7618e-11 5.79027e-11 4.26698e-12"/>
      <geom type="mesh" mesh="mesh_75" pos="2.1684e-19 0.0015875 -0.003175" rgba="0.615686 0.811765 0.929412 1"/>
      

      <joint name="Revolute 16_0" pos="0 0 0" axis="0 -1 0" damping="0.0000001" frictionloss="0"/>
      <body name="Part 2" pos="0 0.0015875 0.00821442" quat="1 0 0 0">
        <inertial pos="0 0 0.0152573" mass="2.39969e-07" diaginertia="1.91942e-11 1.93075e-11 1e-12"/>
        <joint name="Slider 1_0" pos="0 0 0" axis="0 0 -1" type="slide" range="-.02 0" actuatorfrcrange="-1 1" damping="0.0000001" frictionloss="0"/>
        <geom type="mesh" mesh="mesh_91" pos="0 -1.94413e-19 -0.03175" rgba="0.647059 0. 0.647059 1"/>
        

        <body name="Part 3_1" pos="0 0.00079375 0.028575" quat="-0.146743 1.50713e-06 -0.989175 -1.50713e-06">
          <inertial pos="0 0.00357187 0" mass="1.69678e-07" diaginertia="1.25612e-12 1.06904e-12 1.25612e-12"/>
          <joint name="Revolute 18_0" pos="0 0 0" axis="0 -1 0" damping="0.0000001" frictionloss="0"/>
          <geom type="mesh" mesh="mesh_95" pos="-4.11997e-18 0.0079375 -0.060325" rgba="0.231373 0.2 0.705882 1"/>
          <site name="loop_side_A" pos="0 0 0" size="0.002" rgba="1 0 0 0"/>
        </body>
      </body>
    </body>
    </body>
  </worldbody>
  <equality>
        <connect name="close_gripper_loop" site1="loop_side_A" site2="loop_side_B" solimp="0.99 0.99 0.001" solref="0.005 1"/>
    </equality>
     <equality>
        <connect name="close_gripper_loop2" site1="loop_side_A" site2="loop_side_C" solimp="0.99 0.99 0.001" solref="0.005 1"/>
    </equality>
    <equality>
        <connect name="close_gripper_loop3" site1="loop_side_D" site2="loop_side_E"/>
    </equality>
    <equality>
        <connect name="close_gripper_loop4" site1="loop_side_F" site2="loop_side_G"/>
    </equality>
    <equality>
        <connect name="close_gripper_loop5" site1="loop_side_G" site2="loop_side_H"/>
    </equality> -->
    <actuator>
        <position name="gripper_servo" joint="Slider 1_0" kp="0.005" ctrlrange="-0.02 0" forcerange="-0.0005 0.0050"/>
    </actuator>
</mujoco>
