<!--URDF generated by ONSHAPE BY PTC INC, 1.212-->
<robot name="assembly_2">
    <link name="Part 1">
        <inertial>
            <mass value="7.2074e-07" />
            <origin xyz="3.46772e-19 0.0015875 0.0134123" rpy="0 -0 0" />
            <inertia ixx="5.7618e-11" ixy="0" ixz="0" iyy="5.79027e-11" iyz="0" izz="4.26698e-12" />
        </inertial>
        <visual>
            <origin xyz="2.1684e-19 0.0015875 -0.003175" rpy="0 -0 0" />
            <geometry>
                <mesh filename="meshes/75.stl" scale="1 1 1" />
            </geometry>
            <material name="0.615686_0.811765_0.929412_0.000000_0.000000">
                <texture />
                <color rgba="0.615686 0.811765 0.929412 1" />
            </material>
        </visual>
    </link>
    <link name="Part 10">
        <inertial>
            <mass value="1.37134e-06" />
            <origin xyz="-0.0113644 -3.46945e-18 -0.003175" rpy="0 -0 0" />
            <inertia ixx="2.02956e-11" ixy="0" ixz="0" iyy="7.4567e-11" iyz="0" izz="6.02994e-11" />
        </inertial>
        <visual>
            <origin xyz="0.0625709 0.0161285 -0.009525" rpy="0 -0 0" />
            <geometry>
                <mesh filename="meshes/114.stl" scale="1 1 1" />
            </geometry>
            <material name="0.647059_0.647059_0.647059_0.000000_0.000000">
                <texture />
                <color rgba="0.647059 0.647059 0.647059 1" />
            </material>
        </visual>
    </link>
    <link name="Part 11">
        <inertial>
            <mass value="5.01352e-07" />
            <origin xyz="0.0127843 0.00693573 0.0015875" rpy="0 -0 0" />
            <inertia ixx="1.08214e-11" ixy="0" ixz="0" iyy="3.31197e-11" iyz="0" izz="4.30987e-11" />
        </inertial>
        <visual>
            <origin xyz="0.0836005 0.0161285 0" rpy="0 -0 0" />
            <geometry>
                <mesh filename="meshes/118.stl" scale="1 1 1" />
            </geometry>
            <material name="0.231373_0.380392_0.705882_0.000000_0.000000">
                <texture />
                <color rgba="0.231373 0.380392 0.705882 1" />
            </material>
        </visual>
    </link>
    <link name="Part 13">
        <inertial>
            <mass value="0.000117271" />
            <origin xyz="-0.00339204 0.000372157 -2.03931e-06" rpy="0 -0 0" />
            <inertia ixx="3.37885e-07" ixy="0" ixz="0" iyy="1.69104e-07" iyz="0" izz="1.70696e-07" />
        </inertial>
        <visual>
            <origin xyz="-0.0297178 0.0415285 -0.0015875" rpy="0 -0 0" />
            <geometry>
                <mesh filename="meshes/67.stl" scale="1 1 1" />
            </geometry>
            <material name="0.768627_0.886275_0.952941_0.000000_0.000000">
                <texture />
                <color rgba="0.768627 0.886275 0.952941 1" />
            </material>
        </visual>
    </link>
    <link name="Part 14">
        <inertial>
            <mass value="1.44792e-07" />
            <origin xyz="-2.08167e-17 0 -0.0047625" rpy="0 -0 0" />
            <inertia ixx="1.38661e-12" ixy="0" ixz="0" iyy="1.38661e-12" iyz="0" izz="5.83836e-13" />
        </inertial>
        <visual>
            <origin xyz="0.0320173 0.000641214 0" rpy="0 -0 0" />
            <geometry>
                <mesh filename="meshes/59.stl" scale="1 1 1" />
            </geometry>
            <material name="0.972549_0.529412_0.003922_0.000000_0.000000">
                <texture />
                <color rgba="0.972549 0.529412 0.00392157 1" />
            </material>
        </visual>
    </link>
    <link name="Part 14_1">
        <inertial>
            <mass value="1.44792e-07" />
            <origin xyz="-2.08167e-17 0 0.0047625" rpy="0 -0 0" />
            <inertia ixx="1.38661e-12" ixy="0" ixz="0" iyy="1.38661e-12" iyz="0" izz="5.83836e-13" />
        </inertial>
        <visual>
            <origin xyz="0.0320173 0.000641214 0.009525" rpy="0 -0 0" />
            <geometry>
                <mesh filename="meshes/59.stl" scale="1 1 1" />
            </geometry>
            <material name="0.972549_0.529412_0.003922_0.000000_0.000000">
                <texture />
                <color rgba="0.972549 0.529412 0.00392157 1" />
            </material>
        </visual>
    </link>
    <link name="Part 1_1">
        <inertial>
            <mass value="2.94369e-07" />
            <origin xyz="0.00101609 0.00806424 -0.0015875" rpy="0 -0 0" />
            <inertia ixx="9.23311e-12" ixy="0" ixz="0" iyy="1.03422e-12" iyz="0" izz="9.77276e-12" />
        </inertial>
        <visual>
            <origin xyz="0.00203219 0.0161285 -0.003175" rpy="0 -0 0" />
            <geometry>
                <mesh filename="meshes/110.stl" scale="1 1 1" />
            </geometry>
            <material name="0.615686_0.811765_0.929412_0.000000_0.000000">
                <texture />
                <color rgba="0.615686 0.811765 0.929412 1" />
            </material>
        </visual>
    </link>
    <link name="Part 2">
        <inertial>
            <mass value="2.39969e-07" />
            <origin xyz="2.2187e-18 -2.46996e-20 0.0152573" rpy="0 -0 0" />
            <inertia ixx="1.91942e-11" ixy="0" ixz="0" iyy="1.93075e-11" iyz="0" izz="3.83009e-13" />
        </inertial>
        <visual>
            <origin xyz="0 -1.94413e-19 -0.03175" rpy="0 -0 0" />
            <geometry>
                <mesh filename="meshes/91.stl" scale="1 1 1" />
            </geometry>
            <material name="0.647059_0.647059_0.647059_0.000000_0.000000">
                <texture />
                <color rgba="0.647059 0.647059 0.647059 1" />
            </material>
        </visual>
    </link>
    <link name="Part 2_1">
        <inertial>
            <mass value="4.21116e-07" />
            <origin xyz="0.0109792 0.00498325 0.0015875" rpy="0 -0 0" />
            <inertia ixx="5.4424e-12" ixy="0" ixz="0" iyy="2.14811e-11" iyz="0" izz="2.6216e-11" />
        </inertial>
        <visual>
            <origin xyz="0.0219584 0.0099665 0" rpy="0 -0 0" />
            <geometry>
                <mesh filename="meshes/106.stl" scale="1 1 1" />
            </geometry>
            <material name="0.647059_0.647059_0.647059_0.000000_0.000000">
                <texture />
                <color rgba="0.647059 0.647059 0.647059 1" />
            </material>
        </visual>
    </link>
    <link name="Part 3">
        <inertial>
            <mass value="2.26781e-06" />
            <origin xyz="-0.0165991 2.08167e-17 -0.00635" rpy="0 -0 0" />
            <inertia ixx="3.65735e-11" ixy="0" ixz="0" iyy="2.74421e-10" iyz="0" izz="2.47732e-10" />
        </inertial>
        <visual>
            <origin xyz="0.00203219 0.0161285 -0.0127" rpy="0 -0 0" />
            <geometry>
                <mesh filename="meshes/79.stl" scale="1 1 1" />
            </geometry>
            <material name="0.231373_0.380392_0.705882_0.000000_0.000000">
                <texture />
                <color rgba="0.231373 0.380392 0.705882 1" />
            </material>
        </visual>
    </link>
    <link name="Part 3_1">
        <inertial>
            <mass value="1.69678e-07" />
            <origin xyz="-1.66573e-19 0.00357187 -1.38778e-17" rpy="0 -0 0" />
            <inertia ixx="1.25612e-12" ixy="0" ixz="0" iyy="1.06904e-12" iyz="0" izz="1.25612e-12" />
        </inertial>
        <visual>
            <origin xyz="-4.11997e-18 0.0079375 -0.060325" rpy="0 -0 0" />
            <geometry>
                <mesh filename="meshes/95.stl" scale="1 1 1" />
            </geometry>
            <material name="0.231373_0.380392_0.705882_0.000000_0.000000">
                <texture />
                <color rgba="0.231373 0.380392 0.705882 1" />
            </material>
        </visual>
    </link>
    <link name="Part 4">
        <inertial>
            <mass value="2.93711e-07" />
            <origin xyz="0.00749939 0.00308099 -0.0015875" rpy="0 -0 0" />
            <inertia ixx="2.11418e-12" ixy="0" ixz="0" iyy="8.09381e-12" iyz="0" izz="9.71452e-12" />
        </inertial>
        <visual>
            <origin xyz="0.0369572 0.0161285 -0.003175" rpy="0 -0 0" />
            <geometry>
                <mesh filename="meshes/87.stl" scale="1 1 1" />
            </geometry>
            <material name="0.917647_0.917647_0.917647_0.000000_0.000000">
                <texture />
                <color rgba="0.917647 0.917647 0.917647 1" />
            </material>
        </visual>
    </link>
    <link name="Part 5">
        <inertial>
            <mass value="1.55298e-06" />
            <origin xyz="-0.0128069 1.38778e-17 -0.003175" rpy="0 -0 0" />
            <inertia ixx="2.42563e-11" ixy="0" ixz="0" iyy="1.03609e-10" iyz="0" izz="8.6119e-11" />
        </inertial>
        <visual>
            <origin xyz="0.0369572 0.0161285 -0.009525" rpy="0 -0 0" />
            <geometry>
                <mesh filename="meshes/71.stl" scale="1 1 1" />
            </geometry>
            <material name="0.768627_0.886275_0.952941_0.000000_0.000000">
                <texture />
                <color rgba="0.768627 0.886275 0.952941 1" />
            </material>
        </visual>
    </link>
    <link name="Part 6">
        <inertial>
            <mass value="3.01674e-07" />
            <origin xyz="-0.00583411 0.00540861 -0.00107954" rpy="0 -0 0" />
            <inertia ixx="4.73005e-12" ixy="0" ixz="0" iyy="5.28672e-12" iyz="0" izz="8.69255e-12" />
        </inertial>
        <visual>
            <origin xyz="0.0219584 0.0099665 -0.003175" rpy="0 -0 0" />
            <geometry>
                <mesh filename="meshes/63.stl" scale="1 1 1" />
            </geometry>
            <material name="0.972549_0.529412_0.003922_0.000000_0.000000">
                <texture />
                <color rgba="0.972549 0.529412 0.00392157 1" />
            </material>
        </visual>
    </link>
    <link name="Part 7">
        <inertial>
            <mass value="2.94369e-07" />
            <origin xyz="0.00246993 0.00774363 0.0015875" rpy="0 -0 0" />
            <inertia ixx="8.58384e-12" ixy="0" ixz="0" iyy="1.68349e-12" iyz="0" izz="9.77276e-12" />
        </inertial>
        <visual>
            <origin xyz="0.0369572 0.0161285 0" rpy="0 -0 0" />
            <geometry>
                <mesh filename="meshes/83.stl" scale="1 1 1" />
            </geometry>
            <material name="0.498039_0.498039_0.498039_0.000000_0.000000">
                <texture />
                <color rgba="0.498039 0.498039 0.498039 1" />
            </material>
        </visual>
    </link>
    <link name="Part 8">
        <inertial>
            <mass value="4.52574e-07" />
            <origin xyz="-0.0130073 -0.000807897 -0.0015875" rpy="0 -0 0" />
            <inertia ixx="1.49102e-12" ixy="0" ixz="0" iyy="3.14286e-11" iyz="0" izz="3.21592e-11" />
        </inertial>
        <visual>
            <origin xyz="0.0320173 0.000641214 -0.003175" rpy="0 -0 0" />
            <geometry>
                <mesh filename="meshes/122.stl" scale="1 1 1" />
            </geometry>
            <material name="0.980392_0.713725_0.003922_0.000000_0.000000">
                <texture />
                <color rgba="0.980392 0.713726 0.00392157 1" />
            </material>
        </visual>
    </link>
    <link name="Part 9">
        <inertial>
            <mass value="2.67582e-07" />
            <origin xyz="-0.0022695 -0.00693573 -0.0015875" rpy="0 -0 0" />
            <inertia ixx="6.60163e-12" ixy="0" ixz="0" iyy="1.4407e-12" iyz="0" izz="7.59277e-12" />
        </inertial>
        <visual>
            <origin xyz="0.0580319 0.00225701 -0.003175" rpy="0 -0 0" />
            <geometry>
                <mesh filename="meshes/102.stl" scale="1 1 1" />
            </geometry>
            <material name="0.615686_0.811765_0.929412_0.000000_0.000000">
                <texture />
                <color rgba="0.615686 0.811765 0.929412 1" />
            </material>
        </visual>
    </link>
    <link name="root" />
    <joint name="Fastened 1_0" type="fixed">
        <origin xyz="0 0 -8.67362e-19" rpy="-3.14159 3.57453e-30 -9.36772e-31" />
        <axis xyz="1 0 0" />
        <parent link="root" />
        <child link="Part 13" />
    </joint>
    <joint name="Fastened 2_0" type="fixed">
        <origin xyz="0 -6.93889e-18 0.009525" rpy="3.14159 -2.73907e-16 4.09004e-15" />
        <axis xyz="0 0 1" />
        <parent link="Part 14_1" />
        <child link="Part 8" />
    </joint>
    <joint name="Fastened 3_0" type="fixed">
        <origin xyz="-0.0260146 -0.00161579 -1.73472e-18" rpy="-3.14159 -2.73907e-16 4.29561e-15" />
        <axis xyz="0 0 1" />
        <parent link="Part 8" />
        <child link="Part 14" />
    </joint>
    <joint name="Revolute 10_0" type="continuous">
        <origin xyz="-0.0210296 4.16334e-16 0.003175" rpy="-1.67606e-17 -7.87781e-17 -5.32074e-14" />
        <axis xyz="0 0 -1" />
        <parent link="Part 10" />
        <child link="Part 11" />
    </joint>
    <joint name="Revolute 12_0" type="continuous">
        <origin xyz="0.00493986 0.0154873 0" rpy="-3.14159 3.63272e-16 -0.750377" />
        <axis xyz="0 0 -1" />
        <parent link="Part 7" />
        <child link="Part 14_1" />
    </joint>
    <joint name="Revolute 13_0" type="continuous">
        <origin xyz="-0.0256137 5.55112e-17 -0.009525" rpy="-4.2414e-23 1.04324e-22 -2.2789" />
        <axis xyz="0 0 1" />
        <parent link="Part 5" />
        <child link="Part 9" />
    </joint>
    <joint name="Revolute 15_0" type="continuous">
        <origin xyz="-0.03175 0.0254 -0.0015875" rpy="3.60892e-16 -2.25797e-16 -9.90616e-16" />
        <axis xyz="0 0 1" />
        <parent link="Part 13" />
        <child link="Part 3" />
    </joint>
    <joint name="Revolute 16_0" type="continuous">
        <origin xyz="-0.0127 0.06985 -0.0015875" rpy="-1.5708 -3.10862e-15 2.46516" />
        <axis xyz="0 -1 0" />
        <parent link="Part 13" />
        <child link="Part 1" />
    </joint>
    <joint name="Revolute 18_0" type="continuous">
        <origin xyz="1.29063e-15 0.00079375 0.028575" rpy="3.14159 0.294549 -3.14159" />
        <axis xyz="0 -1 0" />
        <parent link="Part 2" />
        <child link="Part 3_1" />
    </joint>
    <joint name="Revolute 1_0" type="continuous">
        <origin xyz="-2.28983e-16 1.73472e-16 -0.0127" rpy="5.84406e-15 -3.71378e-15 0.372725" />
        <axis xyz="0 0 1" />
        <parent link="Part 3" />
        <child link="Part 1_1" />
    </joint>
    <joint name="Revolute 3_0" type="continuous">
        <origin xyz="-0.034925 -2.70617e-16 -0.003175" rpy="-2.05995e-19 3.7473e-18 -0.0242397" />
        <axis xyz="0 0 1" />
        <parent link="Part 3" />
        <child link="Part 5" />
    </joint>
    <joint name="Revolute 4_0" type="continuous">
        <origin xyz="0.0149988 0.00616197 -1.2837e-16" rpy="2.06304e-18 1.24697e-17 -1.12648" />
        <axis xyz="0 0 1" />
        <parent link="Part 4" />
        <child link="Part 2_1" />
    </joint>
    <joint name="Revolute 5_0" type="continuous">
        <origin xyz="0.0149988 0.00616197 -0.003175" rpy="9.05192e-18 3.65436e-17 1.46466e-13" />
        <axis xyz="0 0 1" />
        <parent link="Part 4" />
        <child link="Part 6" />
    </joint>
    <joint name="Revolute 6_0" type="continuous">
        <origin xyz="-0.034925 -1.94289e-16 -0.0127" rpy="4.09602e-15 -5.58166e-15 0.744605" />
        <axis xyz="0 0 -1" />
        <parent link="Part 3" />
        <child link="Part 4" />
    </joint>
    <joint name="Revolute 7_0" type="continuous">
        <origin xyz="-0.0256137 -1.76942e-16 -2.60209e-18" rpy="-3.46599e-16 -3.03937e-16 0.862696" />
        <axis xyz="0 0 -1" />
        <parent link="Part 5" />
        <child link="Part 10" />
    </joint>
    <joint name="Revolute 8_0" type="continuous">
        <origin xyz="-0.034925 -2.5327e-16 -3.68629e-18" rpy="-3.84651e-16 -4.17259e-16 0.744605" />
        <axis xyz="0 0 -1" />
        <parent link="Part 3" />
        <child link="Part 7" />
    </joint>
    <joint name="Slider 1_0" type="prismatic">
        <origin xyz="1.02696e-15 0.0015875 0.00821442" rpy="-4.87407e-17 -1.55431e-15 2.68643e-16" />
        <axis xyz="0 0 -1" />
        <parent link="Part 1" />
        <child link="Part 2" />
        <limit effort="1" velocity="1" lower="-10000" upper="10000" />
    </joint>
</robot>
